<?xml version="1.0" ?>
<sdf version='1.4'>
  <model name='two_wheeled_robot'>
    <link name='base_link'>
      <pose>0 0 0 0 0 0</pose>
      <!--<inertial>
        <inertia>
          <iyy>1000</iyy>
        </inertia>
      </inertial>-->
    </link>
    <link name='left_wheel'>
      <pose>0.000000 0.5 0.5 1.57 3.14 0.000000</pose>
      <inertial>
        <pose>0. 0. 0. 0. 0.000000 0.000000</pose>
        <mass>5</mass>
        <inertia>
          <ixx>0.317</ixx>
          <ixy>0.0</ixy>
          <ixz>0.0</ixz>
          <iyy>0.317</iyy>
          <iyz>0.0</iyz>
          <izz>0.625</izz>
        </inertia>
      </inertial>
      <collision name='left_wheel_collision'>
        <pose>0.000000 0. 0. 0. 0.000000 0.000000</pose>
        <geometry>
          <cylinder>
            <radius>0.5</radius>
            <length>0.25</length>
          </cylinder>
        </geometry>
        <surface>
          <friction>
            <ode>
              <mu>1.</mu>
              <mu2>1.</mu2>
            </ode>
          </friction>
        </surface>
      </collision>
      <visual name='left_wheel_visual'>
        <pose>0.000000 0. 0. 0. 0.000000 0.000000</pose>
        <geometry>
          <cylinder>
            <radius>0.5</radius>
            <length>0.25</length>
          </cylinder>
        </geometry>
        <material>
          <script>
            <name>Gazebo/Green</name>
            <uri>__default__</uri>
          </script>
        </material>
      </visual>
    </link>
    <joint name='left_wheel_joint' type='revolute'>
      <child>left_wheel</child>
      <parent>horizontal_connector</parent>
      <axis>
        <limit>
          <lower>-100000000000000000000</lower>
          <upper>100000000000000000000</upper>
        </limit>
        <dynamics>
          <damping>0.000000</damping>
        </dynamics>
        <xyz>0.000000 1.000000 0.000000</xyz>
      </axis>
    </joint>-->
    <link name='right_wheel'>
      <pose>0. -0.5 0.5 1.57 0. 0.000000</pose>
      <inertial>
        <pose>0. 0. 0. 0. 0.000000 0.000000</pose>
        <mass>5</mass>
        <inertia>
          <ixx>0.317</ixx>
          <ixy>0.0</ixy>
          <ixz>0.0</ixz>
          <iyy>0.317</iyy>
          <iyz>0.0</iyz>
          <izz>0.625</izz>
        </inertia>
      </inertial>
      <collision name='right_wheel_collision'>
        <pose>0.000000 0. 0. 0. 0.000000 0.000000</pose>
        <geometry>
          <cylinder>
            <radius>0.5</radius>
            <length>0.25</length>
          </cylinder>
        </geometry>
        <surface>
          <friction>
            <ode>
              <mu>1.</mu>
              <mu2>1.</mu2>
            </ode>
          </friction>
        </surface>
      </collision>
      <visual name='right_wheel_visual'>
        <pose>0.000000 0. 0. 0. 0.000000 0.000000</pose>
        <geometry>
          <cylinder>
            <radius>0.5</radius>
            <length>0.25</length>
          </cylinder>
        </geometry>
        <material>
          <script>
            <name>Gazebo/Green</name>
            <uri>__default__</uri>
          </script>
        </material>
      </visual>
    </link>
    <joint name='right_wheel_joint' type='revolute'>
      <child>right_wheel</child>
      <parent>horizontal_connector</parent>
      <axis>
        <limit>
          <lower>-100000000000000000000</lower>
          <upper>100000000000000000000</upper>
        </limit>
        <dynamics>
          <damping>0.000000</damping>
        </dynamics>
        <xyz>0.000000 1.000000 0.000000</xyz>
      </axis>
    </joint>
    <link name='horizontal_connector'>
      <pose>0. 0.000000 0.5 1.57 0.000000 0.000000</pose>
      <inertial>
        <pose>0. 0.000000 0. 0. 0.000000 0.000000</pose>
        <mass>1</mass>
        <inertia>
          <ixx>0.317</ixx>-->
          <!--<ixx>1000.</ixx>-->
          <ixy>0.0</ixy>
          <ixz>0.0</ixz>
          <iyy>0.494</iyy>-->
          <!--<iyy>1000.</iyy>-->
          <iyz>0.0</iyz>
          <!--<izz>0.494</izz>-->
          <izz>1000.</izz>
        </inertia>
      </inertial>
      <collision name='horizontal_connector_collision'>
        <pose>0.000000 0.000000 0. 0. 0.000000 0.000000</pose>
        <geometry>
          <cylinder>
            <radius>0.1</radius>
            <length>0.75</length>
          </cylinder>
        </geometry>
      </collision>
      <visual name='horizontal_connector_visual'>
        <pose>0.000000 0.000000 0. 0. 0.000000 0.000000</pose>
        <geometry>
          <cylinder>
            <radius>0.1</radius>
            <length>0.75</length>
          </cylinder>
        </geometry>
        <material>
          <script>
            <name>Gazebo/Gray</name>
            <uri>__default__</uri>
          </script>
        </material>
      </visual>
    </link>
    <joint name='base_joint' type='revolute'>
      <child>horizontal_connector</child>
      <parent>base_link</parent>
      <axis>
        <limit>
          <lower>0</lower>
          <upper>0</upper>
        </limit>
        <dynamics>
          <damping>0.000000</damping>
        </dynamics>
        <xyz>0.000000 1.000000 0.000000</xyz>
      </axis>
    </joint>
    <!--<plugin name="differential_drive_controller" filename="libgazebo_ros_diff_drive.so">
      <leftJoint>left_wheel_joint</leftJoint>
      <rightJoint>right_wheel_joint</rightJoint>
      <wheelSeparation>1.0</wheelSeparation>
      <wheelDiameter>1.0</wheelDiameter>
      <torque>1000</torque>
    </plugin>-->
    <plugin name="DifferentialDrivePlugin" filename="libDifferentialDrivePlugin.so">
    </plugin>-->
  </model>
  
</sdf>
